/**
 *
 * 2650. 设计可取消函数
 *
 * 有时候你会有一个长时间运行的任务，并且你可能希望在它完成之前取消它。为了实现这个目标，请你编写一个名为 cancellable 的函数，它接收一个生成器对象，并返回一个包含两个值的数组：一个 取消函数 和一个 promise 对象。

 你可以假设生成器函数只会生成 promise 对象。你的函数负责将 promise 对象解析的值传回生成器。如果 promise 被拒绝，你的函数应将该错误抛回给生成器。

 如果在生成器完成之前调用了取消回调函数，则你的函数应该将错误抛回给生成器。该错误应该是字符串 "Cancelled"（而不是一个 Error 对象）。如果错误被捕获，则返回的 promise 应该解析为下一个生成或返回的值。否则，promise 应该被拒绝并抛出该错误。不应执行任何其他代码。

 当生成器完成时，您的函数返回的 promise 应该解析为生成器返回的值。但是，如果生成器抛出错误，则返回的 promise 应该拒绝并抛出该错误。

 下面是您的代码应如何使用的示例：

 function* tasks() {
  const val = yield new Promise(resolve => resolve(2 + 2));
  yield new Promise(resolve => setTimeout(resolve, 100));
  return val + 1; // calculation shouldn't be done.
}
 const [cancel, promise] = cancellable(tasks());
 setTimeout(cancel, 50);
 promise.catch(console.log); // logs "Cancelled" at t=50ms
 如果相反， cancel() 没有被调用或者在 t=100ms 之后才被调用，那么 Promise 应被解析为 5 。

  

 示例 1：

 输入：
 generatorFunction = function*() {
  return 42;
}
 cancelledAt = 100
 输出：{"resolved": 42}
 解释：
 const generator = generatorFunction();
 const [cancel, promise] = cancellable(generator);
 setTimeout(cancel, 100);
 promise.then(console.log); // 在 t=0ms 解析为 42

 该生成器立即生成 42 并完成。因此，返回的 promise 立即解析为 42。请注意，取消已经完成的生成器没有任何作用。
 示例 2：

 输入：
 generatorFunction = function*() {
  const msg = yield new Promise(res => res("Hello"));
  throw `Error: ${msg}`;
}
 cancelledAt = null
 输出：{"rejected": "Error: Hello"}
 解释：
 一个 Promise 被生成。该函数通过等待 promise 解析并将解析后的值传回生成器来处理它。然后抛出一个错误，这会导致 promise 被同样抛出的错误拒绝。
 示例 3：

 输入：
 generatorFunction = function*() {
  yield new Promise(res => setTimeout(res, 200));
  return "Success";
}
 cancelledAt = 100
 输出：{"rejected": "Cancelled"}
 解释：
 当函数等待被生成的 promise 解析时，cancel() 被调用。这会导致一个错误消息被发送回生成器。由于这个错误没有被捕获，返回的 promise 会因为这个错误而被拒绝。
 示例 4：

 输入：
 generatorFunction = function*() {
  let result = 0;
  yield new Promise(res => setTimeout(res, 100));
  result += yield new Promise(res => res(1));
  yield new Promise(res => setTimeout(res, 100));
  result += yield new Promise(res => res(1));
  return result;
}
 cancelledAt = null
 输出：{"resolved": 2}
 解释：
 生成器生成了 4 个 promise 。其中两个 promise 的值被添加到结果中。200ms 后，生成器以值 2 完成，该值被返回的 promise 解析。
 示例 5：

 输入：
 generatorFunction = function*() {
  let result = 0;
  try {
    yield new Promise(res => setTimeout(res, 100));
    result += yield new Promise(res => res(1));
    yield new Promise(res => setTimeout(res, 100));
    result += yield new Promise(res => res(1));
  } catch(e) {
    return result;
  }
  return result;
}
 cancelledAt = 150
 输出：{"resolved": 1}
 解释：
 前两个生成的 promise 解析并导致结果递增。然而，在 t=150ms 时，生成器被取消了。发送给生成器的错误被捕获，结果被返回并最终由返回的 promise 解析。
 示例 6：

 输入：
 generatorFunction = function*() {
  try {
    yield new Promise((resolve, reject) => reject("Promise Rejected"));
  } catch(e) {
    let a = yield new Promise(resolve => resolve(2));
    let b = yield new Promise(resolve => resolve(2));
    return a + b;
  };
}
 cancelledAt = null
 输出：{"resolved": 4}
 解释：
 第一个生成的 promise 立即被拒绝。该错误被捕获。因为生成器没有被取消，执行继续像往常一样。最终解析为 2 + 2 = 4。
  

 提示：

 cancelledAt == null or 0 <= cancelledAt <= 1000
 generatorFunction 返回一个生成器对象

 来源：力扣（LeetCode）
 链接：https://leetcode.cn/problems/design-cancellable-function
 著作权归领扣网络所有。商业转载请联系官方授权，非商业转载请注明出处。
 */


/**
 * @param {Generator} generator
 * @return {[Function, Promise]}
 */
var cancellable = function(generator) {

};

/**
 * function* tasks() {
 *   const val = yield new Promise(resolve => resolve(2 + 2));
 *   yield new Promise(resolve => setTimeout(resolve, 100));
 *   return val + 1;
 * }
 * const [cancel, promise] = cancellable(tasks());
 * setTimeout(cancel, 50);
 * promise.catch(console.log); // logs "Cancelled" at t=50ms
 */